{
 "cells": [
  {
   "cell_type": "markdown",
   "metadata": {},
   "source": [
    "## 设计基函数(basis function) 以及数据读取"
   ]
  },
  {
   "cell_type": "code",
   "execution_count": null,
   "metadata": {
    "is_executing": true
   },
   "outputs": [],
   "source": [
    "import numpy as np\n",
    "import matplotlib.pyplot as plt\n",
    "\n",
    "def identity_basis(x):\n",
    "    ret = np.expand_dims(x, axis=1)\n",
    "    return ret\n",
    "\n",
    "def multinomial_basis(x, feature_num=10):\n",
    "    x = np.expand_dims(x, axis=1) # shape(N, 1)\n",
    "    feat = [x]\n",
    "    for i in range(2, feature_num+1):\n",
    "        feat.append(x**i)\n",
    "    ret = np.concatenate(feat, axis=1)\n",
    "    return ret\n",
    "\n",
    "def gaussian_basis(x, feature_num=10):\n",
    "    centers = np.linspace(0, 25, feature_num)\n",
    "    width = 1.0 * (centers[1] - centers[0])\n",
    "    x = np.expand_dims(x, axis=1)\n",
    "    x = np.concatenate([x]*feature_num, axis=1)\n",
    "    \n",
    "    out = (x-centers)/width\n",
    "    ret = np.exp(-0.5 * out ** 2)\n",
    "    return ret\n",
    "\n",
    "def load_data(filename, basis_func=gaussian_basis):\n",
    "    \"\"\"载入数据。\"\"\"\n",
    "    xys = []\n",
    "    with open(filename, 'r') as f:\n",
    "        for line in f:\n",
    "            xys.append(map(float, line.strip().split()))\n",
    "        xs, ys = zip(*xys)\n",
    "        xs, ys = np.asarray(xs), np.asarray(ys)\n",
    "        \n",
    "        o_x, o_y = xs, ys\n",
    "        phi0 = np.expand_dims(np.ones_like(xs), axis=1)\n",
    "        phi1 = basis_func(xs)\n",
    "        xs = np.concatenate([phi0, phi1], axis=1)\n",
    "        return (np.float32(xs), np.float32(ys)), (o_x, o_y)"
   ]
  },
  {
   "cell_type": "markdown",
   "metadata": {},
   "source": [
    "## 定义模型"
   ]
  },
  {
   "cell_type": "code",
   "execution_count": 2,
   "metadata": {
    "ExecuteTime": {
     "end_time": "2024-01-24T09:44:28.098204900Z",
     "start_time": "2024-01-24T09:44:10.666501200Z"
    }
   },
   "outputs": [],
   "source": [
    "import tensorflow as tf\n",
    "from tensorflow.keras import optimizers, layers, Model\n",
    "\n",
    "class linearModel(Model):\n",
    "    def __init__(self, ndim):\n",
    "        super(linearModel, self).__init__()\n",
    "        self.w = tf.Variable(\n",
    "            shape=[ndim, 1], \n",
    "            initial_value=tf.random.uniform(\n",
    "                [ndim,1], minval=-0.1, maxval=0.1, dtype=tf.float32))\n",
    "        \n",
    "    @tf.function\n",
    "    def call(self, x):\n",
    "        y = tf.squeeze(tf.matmul(x, self.w), axis=1)\n",
    "        return y\n",
    "\n",
    "(xs, ys), (o_x, o_y) = load_data('train.txt')        \n",
    "ndim = xs.shape[1]\n",
    "\n",
    "model = linearModel(ndim=ndim)\n"
   ]
  },
  {
   "cell_type": "markdown",
   "metadata": {},
   "source": [
    "## 训练以及评估"
   ]
  },
  {
   "cell_type": "code",
   "execution_count": 3,
   "metadata": {
    "ExecuteTime": {
     "end_time": "2024-01-24T09:44:33.333987200Z",
     "start_time": "2024-01-24T09:44:33.317023200Z"
    }
   },
   "outputs": [],
   "source": [
    "optimizer = optimizers.Adam(0.1)\n",
    "@tf.function\n",
    "def train_one_step(model, xs, ys):\n",
    "    with tf.GradientTape() as tape:\n",
    "        y_preds = model(xs)\n",
    "        loss = tf.reduce_mean(tf.sqrt(1e-12+(ys-y_preds)**2))\n",
    "    grads = tape.gradient(loss, model.w)\n",
    "    optimizer.apply_gradients([(grads, model.w)])\n",
    "    return loss\n",
    "\n",
    "@tf.function\n",
    "def predict(model, xs):\n",
    "    y_preds = model(xs)\n",
    "    return y_preds\n",
    "\n",
    "def evaluate(ys, ys_pred):\n",
    "    \"\"\"评估模型。\"\"\"\n",
    "    std = np.sqrt(np.mean(np.abs(ys - ys_pred) ** 2))\n",
    "    return std"
   ]
  },
  {
   "cell_type": "code",
   "execution_count": null,
   "metadata": {
    "is_executing": true,
    "ExecuteTime": {
     "start_time": "2024-01-24T09:44:36.547689300Z"
    }
   },
   "outputs": [
    {
     "name": "stdout",
     "output_type": "stream",
     "text": [
      "WARNING:tensorflow:Entity <function train_one_step at 0x00000180A7AEBF28> could not be transformed and will be executed as-is. Please report this to the AutoGraph team. When filing the bug, set the verbosity to 10 (on Linux, `export AUTOGRAPH_VERBOSITY=10`) and attach the full output. Cause: cannot import name 'trace'\n",
      "WARNING: Entity <function train_one_step at 0x00000180A7AEBF28> could not be transformed and will be executed as-is. Please report this to the AutoGraph team. When filing the bug, set the verbosity to 10 (on Linux, `export AUTOGRAPH_VERBOSITY=10`) and attach the full output. Cause: cannot import name 'trace'\n",
      "WARNING:tensorflow:Entity <bound method linearModel.call of <tensorflow.python.eager.function.TfMethodTarget object at 0x00000180AE645898>> could not be transformed and will be executed as-is. Please report this to the AutoGraph team. When filing the bug, set the verbosity to 10 (on Linux, `export AUTOGRAPH_VERBOSITY=10`) and attach the full output. Cause: No module named 'tensorflow_core.estimator'\n"
     ]
    },
    {
     "name": "stderr",
     "output_type": "stream",
     "text": [
      "ERROR:root:Internal Python error in the inspect module.\n",
      "Below is the traceback from this internal error.\n",
      "\n"
     ]
    },
    {
     "name": "stdout",
     "output_type": "stream",
     "text": [
      "WARNING: Entity <bound method linearModel.call of <tensorflow.python.eager.function.TfMethodTarget object at 0x00000180AE645898>> could not be transformed and will be executed as-is. Please report this to the AutoGraph team. When filing the bug, set the verbosity to 10 (on Linux, `export AUTOGRAPH_VERBOSITY=10`) and attach the full output. Cause: No module named 'tensorflow_core.estimator'\n"
     ]
    },
    {
     "name": "stderr",
     "output_type": "stream",
     "text": [
      "ERROR:root:Internal Python error in the inspect module.\n",
      "Below is the traceback from this internal error.\n",
      "\n",
      "ERROR:root:Internal Python error in the inspect module.\n",
      "Below is the traceback from this internal error.\n",
      "\n"
     ]
    },
    {
     "name": "stdout",
     "output_type": "stream",
     "text": [
      "Traceback (most recent call last):\n",
      "  File \"D:\\Anaconda3\\envs\\pytorch\\lib\\site-packages\\IPython\\core\\interactiveshell.py\", line 3343, in run_code\n",
      "    exec(code_obj, self.user_global_ns, self.user_ns)\n",
      "  File \"<ipython-input-4-cb2f4baff918>\", line 2, in <module>\n",
      "    loss = train_one_step(model, xs, ys)\n",
      "  File \"D:\\Anaconda3\\envs\\pytorch\\lib\\site-packages\\tensorflow_core\\python\\eager\\def_function.py\", line 449, in __call__\n",
      "    self._initialize(args, kwds, add_initializers_to=initializer_map)\n",
      "  File \"D:\\Anaconda3\\envs\\pytorch\\lib\\site-packages\\tensorflow_core\\python\\eager\\def_function.py\", line 392, in _initialize\n",
      "    *args, **kwds))\n",
      "  File \"D:\\Anaconda3\\envs\\pytorch\\lib\\site-packages\\tensorflow_core\\python\\eager\\function.py\", line 1847, in _get_concrete_function_internal_garbage_collected\n",
      "    graph_function, _, _ = self._maybe_define_function(args, kwargs)\n",
      "  File \"D:\\Anaconda3\\envs\\pytorch\\lib\\site-packages\\tensorflow_core\\python\\eager\\function.py\", line 2147, in _maybe_define_function\n",
      "    graph_function = self._create_graph_function(args, kwargs)\n",
      "  File \"D:\\Anaconda3\\envs\\pytorch\\lib\\site-packages\\tensorflow_core\\python\\eager\\function.py\", line 2038, in _create_graph_function\n",
      "    capture_by_value=self._capture_by_value),\n",
      "  File \"D:\\Anaconda3\\envs\\pytorch\\lib\\site-packages\\tensorflow_core\\python\\framework\\func_graph.py\", line 915, in func_graph_from_py_func\n",
      "    func_outputs = python_func(*func_args, **func_kwargs)\n",
      "  File \"D:\\Anaconda3\\envs\\pytorch\\lib\\site-packages\\tensorflow_core\\python\\eager\\def_function.py\", line 335, in wrapped_fn\n",
      "    return weak_wrapped_fn().__wrapped__(*args, **kwds)\n",
      "  File \"D:\\Anaconda3\\envs\\pytorch\\lib\\site-packages\\tensorflow_core\\python\\framework\\func_graph.py\", line 905, in wrapper\n",
      "    raise e.ag_error_metadata.to_exception(e)\n",
      "AttributeError: in converted code:\n",
      "\n",
      "    <ipython-input-3-0ffb32560183>:7 train_one_step\n",
      "        grads = tape.gradient(loss, model.w)\n",
      "    D:\\Anaconda3\\envs\\pytorch\\lib\\site-packages\\tensorflow_core\\python\\eager\\backprop.py:1015 gradient\n",
      "        unconnected_gradients=unconnected_gradients)\n",
      "    D:\\Anaconda3\\envs\\pytorch\\lib\\site-packages\\tensorflow_core\\python\\eager\\imperative_grad.py:76 imperative_grad\n",
      "        compat.as_str(unconnected_gradients.value))\n",
      "\n",
      "    AttributeError: 'RefVariable' object has no attribute '_id'\n",
      "\n",
      "\n",
      "During handling of the above exception, another exception occurred:\n",
      "\n",
      "Traceback (most recent call last):\n",
      "  File \"D:\\Anaconda3\\envs\\pytorch\\lib\\site-packages\\IPython\\core\\interactiveshell.py\", line 2044, in showtraceback\n",
      "    stb = value._render_traceback_()\n",
      "AttributeError: 'AttributeError' object has no attribute '_render_traceback_'\n",
      "\n",
      "During handling of the above exception, another exception occurred:\n",
      "\n",
      "Traceback (most recent call last):\n",
      "  File \"D:\\Anaconda3\\envs\\pytorch\\lib\\site-packages\\IPython\\core\\ultratb.py\", line 1169, in get_records\n",
      "    return _fixed_getinnerframes(etb, number_of_lines_of_context, tb_offset)\n",
      "  File \"D:\\Anaconda3\\envs\\pytorch\\lib\\site-packages\\IPython\\core\\ultratb.py\", line 316, in wrapped\n",
      "    return f(*args, **kwargs)\n",
      "  File \"D:\\Anaconda3\\envs\\pytorch\\lib\\site-packages\\IPython\\core\\ultratb.py\", line 350, in _fixed_getinnerframes\n",
      "    records = fix_frame_records_filenames(inspect.getinnerframes(etb, context))\n",
      "  File \"D:\\Anaconda3\\envs\\pytorch\\lib\\inspect.py\", line 1490, in getinnerframes\n",
      "    frameinfo = (tb.tb_frame,) + getframeinfo(tb, context)\n",
      "  File \"D:\\Anaconda3\\envs\\pytorch\\lib\\inspect.py\", line 1448, in getframeinfo\n",
      "    filename = getsourcefile(frame) or getfile(frame)\n",
      "  File \"D:\\Anaconda3\\envs\\pytorch\\lib\\inspect.py\", line 696, in getsourcefile\n",
      "    if getattr(getmodule(object, filename), '__loader__', None) is not None:\n",
      "  File \"D:\\Anaconda3\\envs\\pytorch\\lib\\inspect.py\", line 733, in getmodule\n",
      "    if ismodule(module) and hasattr(module, '__file__'):\n",
      "  File \"D:\\Anaconda3\\envs\\pytorch\\lib\\site-packages\\tensorflow\\__init__.py\", line 50, in __getattr__\n",
      "    module = self._load()\n",
      "  File \"D:\\Anaconda3\\envs\\pytorch\\lib\\site-packages\\tensorflow\\__init__.py\", line 44, in _load\n",
      "    module = _importlib.import_module(self.__name__)\n",
      "  File \"D:\\Anaconda3\\envs\\pytorch\\lib\\importlib\\__init__.py\", line 126, in import_module\n",
      "    return _bootstrap._gcd_import(name[level:], package, level)\n",
      "  File \"<frozen importlib._bootstrap>\", line 994, in _gcd_import\n",
      "  File \"<frozen importlib._bootstrap>\", line 971, in _find_and_load\n",
      "  File \"<frozen importlib._bootstrap>\", line 953, in _find_and_load_unlocked\n",
      "ModuleNotFoundError: No module named 'tensorflow_core.estimator'\n",
      "Traceback (most recent call last):\n",
      "  File \"D:\\Anaconda3\\envs\\pytorch\\lib\\site-packages\\IPython\\core\\interactiveshell.py\", line 3343, in run_code\n",
      "    exec(code_obj, self.user_global_ns, self.user_ns)\n",
      "  File \"<ipython-input-4-cb2f4baff918>\", line 2, in <module>\n",
      "    loss = train_one_step(model, xs, ys)\n",
      "  File \"D:\\Anaconda3\\envs\\pytorch\\lib\\site-packages\\tensorflow_core\\python\\eager\\def_function.py\", line 449, in __call__\n",
      "    self._initialize(args, kwds, add_initializers_to=initializer_map)\n",
      "  File \"D:\\Anaconda3\\envs\\pytorch\\lib\\site-packages\\tensorflow_core\\python\\eager\\def_function.py\", line 392, in _initialize\n",
      "    *args, **kwds))\n",
      "  File \"D:\\Anaconda3\\envs\\pytorch\\lib\\site-packages\\tensorflow_core\\python\\eager\\function.py\", line 1847, in _get_concrete_function_internal_garbage_collected\n",
      "    graph_function, _, _ = self._maybe_define_function(args, kwargs)\n",
      "  File \"D:\\Anaconda3\\envs\\pytorch\\lib\\site-packages\\tensorflow_core\\python\\eager\\function.py\", line 2147, in _maybe_define_function\n",
      "    graph_function = self._create_graph_function(args, kwargs)\n",
      "  File \"D:\\Anaconda3\\envs\\pytorch\\lib\\site-packages\\tensorflow_core\\python\\eager\\function.py\", line 2038, in _create_graph_function\n",
      "    capture_by_value=self._capture_by_value),\n",
      "  File \"D:\\Anaconda3\\envs\\pytorch\\lib\\site-packages\\tensorflow_core\\python\\framework\\func_graph.py\", line 915, in func_graph_from_py_func\n",
      "    func_outputs = python_func(*func_args, **func_kwargs)\n",
      "  File \"D:\\Anaconda3\\envs\\pytorch\\lib\\site-packages\\tensorflow_core\\python\\eager\\def_function.py\", line 335, in wrapped_fn\n",
      "    return weak_wrapped_fn().__wrapped__(*args, **kwds)\n",
      "  File \"D:\\Anaconda3\\envs\\pytorch\\lib\\site-packages\\tensorflow_core\\python\\framework\\func_graph.py\", line 905, in wrapper\n",
      "    raise e.ag_error_metadata.to_exception(e)\n",
      "AttributeError: in converted code:\n",
      "\n",
      "    <ipython-input-3-0ffb32560183>:7 train_one_step\n",
      "        grads = tape.gradient(loss, model.w)\n",
      "    D:\\Anaconda3\\envs\\pytorch\\lib\\site-packages\\tensorflow_core\\python\\eager\\backprop.py:1015 gradient\n",
      "        unconnected_gradients=unconnected_gradients)\n",
      "    D:\\Anaconda3\\envs\\pytorch\\lib\\site-packages\\tensorflow_core\\python\\eager\\imperative_grad.py:76 imperative_grad\n",
      "        compat.as_str(unconnected_gradients.value))\n",
      "\n",
      "    AttributeError: 'RefVariable' object has no attribute '_id'\n",
      "\n",
      "\n",
      "During handling of the above exception, another exception occurred:\n",
      "\n",
      "Traceback (most recent call last):\n",
      "  File \"D:\\Anaconda3\\envs\\pytorch\\lib\\site-packages\\IPython\\core\\interactiveshell.py\", line 2044, in showtraceback\n",
      "    stb = value._render_traceback_()\n",
      "AttributeError: 'AttributeError' object has no attribute '_render_traceback_'\n",
      "\n",
      "During handling of the above exception, another exception occurred:\n",
      "\n",
      "Traceback (most recent call last):\n",
      "  File \"D:\\Anaconda3\\envs\\pytorch\\lib\\site-packages\\IPython\\core\\interactiveshell.py\", line 3263, in run_ast_nodes\n",
      "    if (await self.run_code(code, result,  async_=asy)):\n",
      "  File \"D:\\Anaconda3\\envs\\pytorch\\lib\\site-packages\\IPython\\core\\interactiveshell.py\", line 3360, in run_code\n",
      "    self.showtraceback(running_compiled_code=True)\n",
      "  File \"D:\\Anaconda3\\envs\\pytorch\\lib\\site-packages\\IPython\\core\\interactiveshell.py\", line 2047, in showtraceback\n",
      "    value, tb, tb_offset=tb_offset)\n",
      "  File \"D:\\Anaconda3\\envs\\pytorch\\lib\\site-packages\\IPython\\core\\ultratb.py\", line 1436, in structured_traceback\n",
      "    self, etype, value, tb, tb_offset, number_of_lines_of_context)\n",
      "  File \"D:\\Anaconda3\\envs\\pytorch\\lib\\site-packages\\IPython\\core\\ultratb.py\", line 1336, in structured_traceback\n",
      "    self, etype, value, tb, tb_offset, number_of_lines_of_context\n",
      "  File \"D:\\Anaconda3\\envs\\pytorch\\lib\\site-packages\\IPython\\core\\ultratb.py\", line 1193, in structured_traceback\n",
      "    tb_offset)\n",
      "  File \"D:\\Anaconda3\\envs\\pytorch\\lib\\site-packages\\IPython\\core\\ultratb.py\", line 1150, in format_exception_as_a_whole\n",
      "    last_unique, recursion_repeat = find_recursion(orig_etype, evalue, records)\n",
      "  File \"D:\\Anaconda3\\envs\\pytorch\\lib\\site-packages\\IPython\\core\\ultratb.py\", line 451, in find_recursion\n",
      "    return len(records), 0\n",
      "TypeError: object of type 'NoneType' has no len()\n",
      "\n",
      "During handling of the above exception, another exception occurred:\n",
      "\n",
      "Traceback (most recent call last):\n",
      "  File \"D:\\Anaconda3\\envs\\pytorch\\lib\\site-packages\\IPython\\core\\interactiveshell.py\", line 2044, in showtraceback\n",
      "    stb = value._render_traceback_()\n",
      "AttributeError: 'TypeError' object has no attribute '_render_traceback_'\n",
      "\n",
      "During handling of the above exception, another exception occurred:\n",
      "\n",
      "Traceback (most recent call last):\n",
      "  File \"D:\\Anaconda3\\envs\\pytorch\\lib\\site-packages\\IPython\\core\\ultratb.py\", line 1169, in get_records\n",
      "    return _fixed_getinnerframes(etb, number_of_lines_of_context, tb_offset)\n",
      "  File \"D:\\Anaconda3\\envs\\pytorch\\lib\\site-packages\\IPython\\core\\ultratb.py\", line 316, in wrapped\n",
      "    return f(*args, **kwargs)\n",
      "  File \"D:\\Anaconda3\\envs\\pytorch\\lib\\site-packages\\IPython\\core\\ultratb.py\", line 350, in _fixed_getinnerframes\n",
      "    records = fix_frame_records_filenames(inspect.getinnerframes(etb, context))\n",
      "  File \"D:\\Anaconda3\\envs\\pytorch\\lib\\inspect.py\", line 1490, in getinnerframes\n",
      "    frameinfo = (tb.tb_frame,) + getframeinfo(tb, context)\n",
      "  File \"D:\\Anaconda3\\envs\\pytorch\\lib\\inspect.py\", line 1448, in getframeinfo\n",
      "    filename = getsourcefile(frame) or getfile(frame)\n",
      "  File \"D:\\Anaconda3\\envs\\pytorch\\lib\\inspect.py\", line 696, in getsourcefile\n",
      "    if getattr(getmodule(object, filename), '__loader__', None) is not None:\n",
      "  File \"D:\\Anaconda3\\envs\\pytorch\\lib\\inspect.py\", line 733, in getmodule\n",
      "    if ismodule(module) and hasattr(module, '__file__'):\n",
      "  File \"D:\\Anaconda3\\envs\\pytorch\\lib\\site-packages\\tensorflow\\__init__.py\", line 50, in __getattr__\n",
      "    module = self._load()\n",
      "  File \"D:\\Anaconda3\\envs\\pytorch\\lib\\site-packages\\tensorflow\\__init__.py\", line 44, in _load\n",
      "    module = _importlib.import_module(self.__name__)\n",
      "  File \"D:\\Anaconda3\\envs\\pytorch\\lib\\importlib\\__init__.py\", line 126, in import_module\n",
      "    return _bootstrap._gcd_import(name[level:], package, level)\n",
      "  File \"<frozen importlib._bootstrap>\", line 994, in _gcd_import\n",
      "  File \"<frozen importlib._bootstrap>\", line 971, in _find_and_load\n",
      "  File \"<frozen importlib._bootstrap>\", line 953, in _find_and_load_unlocked\n",
      "ModuleNotFoundError: No module named 'tensorflow_core.estimator'\n",
      "Traceback (most recent call last):\n",
      "  File \"D:\\Anaconda3\\envs\\pytorch\\lib\\site-packages\\IPython\\core\\interactiveshell.py\", line 3343, in run_code\n",
      "    exec(code_obj, self.user_global_ns, self.user_ns)\n",
      "  File \"<ipython-input-4-cb2f4baff918>\", line 2, in <module>\n",
      "    loss = train_one_step(model, xs, ys)\n",
      "  File \"D:\\Anaconda3\\envs\\pytorch\\lib\\site-packages\\tensorflow_core\\python\\eager\\def_function.py\", line 449, in __call__\n",
      "    self._initialize(args, kwds, add_initializers_to=initializer_map)\n",
      "  File \"D:\\Anaconda3\\envs\\pytorch\\lib\\site-packages\\tensorflow_core\\python\\eager\\def_function.py\", line 392, in _initialize\n",
      "    *args, **kwds))\n",
      "  File \"D:\\Anaconda3\\envs\\pytorch\\lib\\site-packages\\tensorflow_core\\python\\eager\\function.py\", line 1847, in _get_concrete_function_internal_garbage_collected\n",
      "    graph_function, _, _ = self._maybe_define_function(args, kwargs)\n",
      "  File \"D:\\Anaconda3\\envs\\pytorch\\lib\\site-packages\\tensorflow_core\\python\\eager\\function.py\", line 2147, in _maybe_define_function\n",
      "    graph_function = self._create_graph_function(args, kwargs)\n",
      "  File \"D:\\Anaconda3\\envs\\pytorch\\lib\\site-packages\\tensorflow_core\\python\\eager\\function.py\", line 2038, in _create_graph_function\n",
      "    capture_by_value=self._capture_by_value),\n",
      "  File \"D:\\Anaconda3\\envs\\pytorch\\lib\\site-packages\\tensorflow_core\\python\\framework\\func_graph.py\", line 915, in func_graph_from_py_func\n",
      "    func_outputs = python_func(*func_args, **func_kwargs)\n",
      "  File \"D:\\Anaconda3\\envs\\pytorch\\lib\\site-packages\\tensorflow_core\\python\\eager\\def_function.py\", line 335, in wrapped_fn\n",
      "    return weak_wrapped_fn().__wrapped__(*args, **kwds)\n",
      "  File \"D:\\Anaconda3\\envs\\pytorch\\lib\\site-packages\\tensorflow_core\\python\\framework\\func_graph.py\", line 905, in wrapper\n",
      "    raise e.ag_error_metadata.to_exception(e)\n",
      "AttributeError: in converted code:\n",
      "\n",
      "    <ipython-input-3-0ffb32560183>:7 train_one_step\n",
      "        grads = tape.gradient(loss, model.w)\n",
      "    D:\\Anaconda3\\envs\\pytorch\\lib\\site-packages\\tensorflow_core\\python\\eager\\backprop.py:1015 gradient\n",
      "        unconnected_gradients=unconnected_gradients)\n",
      "    D:\\Anaconda3\\envs\\pytorch\\lib\\site-packages\\tensorflow_core\\python\\eager\\imperative_grad.py:76 imperative_grad\n",
      "        compat.as_str(unconnected_gradients.value))\n",
      "\n",
      "    AttributeError: 'RefVariable' object has no attribute '_id'\n",
      "\n",
      "\n",
      "During handling of the above exception, another exception occurred:\n",
      "\n",
      "Traceback (most recent call last):\n",
      "  File \"D:\\Anaconda3\\envs\\pytorch\\lib\\site-packages\\IPython\\core\\interactiveshell.py\", line 2044, in showtraceback\n",
      "    stb = value._render_traceback_()\n",
      "AttributeError: 'AttributeError' object has no attribute '_render_traceback_'\n",
      "\n",
      "During handling of the above exception, another exception occurred:\n",
      "\n",
      "Traceback (most recent call last):\n",
      "  File \"D:\\Anaconda3\\envs\\pytorch\\lib\\site-packages\\IPython\\core\\interactiveshell.py\", line 3263, in run_ast_nodes\n",
      "    if (await self.run_code(code, result,  async_=asy)):\n",
      "  File \"D:\\Anaconda3\\envs\\pytorch\\lib\\site-packages\\IPython\\core\\interactiveshell.py\", line 3360, in run_code\n",
      "    self.showtraceback(running_compiled_code=True)\n",
      "  File \"D:\\Anaconda3\\envs\\pytorch\\lib\\site-packages\\IPython\\core\\interactiveshell.py\", line 2047, in showtraceback\n",
      "    value, tb, tb_offset=tb_offset)\n",
      "  File \"D:\\Anaconda3\\envs\\pytorch\\lib\\site-packages\\IPython\\core\\ultratb.py\", line 1436, in structured_traceback\n",
      "    self, etype, value, tb, tb_offset, number_of_lines_of_context)\n",
      "  File \"D:\\Anaconda3\\envs\\pytorch\\lib\\site-packages\\IPython\\core\\ultratb.py\", line 1336, in structured_traceback\n",
      "    self, etype, value, tb, tb_offset, number_of_lines_of_context\n",
      "  File \"D:\\Anaconda3\\envs\\pytorch\\lib\\site-packages\\IPython\\core\\ultratb.py\", line 1193, in structured_traceback\n",
      "    tb_offset)\n",
      "  File \"D:\\Anaconda3\\envs\\pytorch\\lib\\site-packages\\IPython\\core\\ultratb.py\", line 1150, in format_exception_as_a_whole\n",
      "    last_unique, recursion_repeat = find_recursion(orig_etype, evalue, records)\n",
      "  File \"D:\\Anaconda3\\envs\\pytorch\\lib\\site-packages\\IPython\\core\\ultratb.py\", line 451, in find_recursion\n",
      "    return len(records), 0\n",
      "TypeError: object of type 'NoneType' has no len()\n",
      "\n",
      "During handling of the above exception, another exception occurred:\n",
      "\n",
      "Traceback (most recent call last):\n",
      "  File \"D:\\Anaconda3\\envs\\pytorch\\lib\\site-packages\\IPython\\core\\interactiveshell.py\", line 2044, in showtraceback\n",
      "    stb = value._render_traceback_()\n",
      "AttributeError: 'TypeError' object has no attribute '_render_traceback_'\n",
      "\n",
      "During handling of the above exception, another exception occurred:\n",
      "\n",
      "Traceback (most recent call last):\n",
      "  File \"D:\\Anaconda3\\envs\\pytorch\\lib\\site-packages\\IPython\\core\\interactiveshell.py\", line 2895, in _run_cell\n",
      "    return runner(coro)\n",
      "  File \"D:\\Anaconda3\\envs\\pytorch\\lib\\site-packages\\IPython\\core\\async_helpers.py\", line 68, in _pseudo_sync_runner\n",
      "    coro.send(None)\n",
      "  File \"D:\\Anaconda3\\envs\\pytorch\\lib\\site-packages\\IPython\\core\\interactiveshell.py\", line 3072, in run_cell_async\n",
      "    interactivity=interactivity, compiler=compiler, result=result)\n",
      "  File \"D:\\Anaconda3\\envs\\pytorch\\lib\\site-packages\\IPython\\core\\interactiveshell.py\", line 3282, in run_ast_nodes\n",
      "    self.showtraceback()\n",
      "  File \"D:\\Anaconda3\\envs\\pytorch\\lib\\site-packages\\IPython\\core\\interactiveshell.py\", line 2047, in showtraceback\n",
      "    value, tb, tb_offset=tb_offset)\n",
      "  File \"D:\\Anaconda3\\envs\\pytorch\\lib\\site-packages\\IPython\\core\\ultratb.py\", line 1436, in structured_traceback\n",
      "    self, etype, value, tb, tb_offset, number_of_lines_of_context)\n",
      "  File \"D:\\Anaconda3\\envs\\pytorch\\lib\\site-packages\\IPython\\core\\ultratb.py\", line 1336, in structured_traceback\n",
      "    self, etype, value, tb, tb_offset, number_of_lines_of_context\n",
      "  File \"D:\\Anaconda3\\envs\\pytorch\\lib\\site-packages\\IPython\\core\\ultratb.py\", line 1211, in structured_traceback\n",
      "    chained_exceptions_tb_offset)\n",
      "  File \"D:\\Anaconda3\\envs\\pytorch\\lib\\site-packages\\IPython\\core\\ultratb.py\", line 1150, in format_exception_as_a_whole\n",
      "    last_unique, recursion_repeat = find_recursion(orig_etype, evalue, records)\n",
      "  File \"D:\\Anaconda3\\envs\\pytorch\\lib\\site-packages\\IPython\\core\\ultratb.py\", line 451, in find_recursion\n",
      "    return len(records), 0\n",
      "TypeError: object of type 'NoneType' has no len()\n",
      "\n",
      "During handling of the above exception, another exception occurred:\n",
      "\n",
      "Traceback (most recent call last):\n",
      "  File \"D:\\Anaconda3\\envs\\pytorch\\lib\\site-packages\\IPython\\core\\interactiveshell.py\", line 2044, in showtraceback\n",
      "    stb = value._render_traceback_()\n",
      "AttributeError: 'TypeError' object has no attribute '_render_traceback_'\n",
      "\n",
      "During handling of the above exception, another exception occurred:\n",
      "\n",
      "Traceback (most recent call last):\n",
      "  File \"D:\\Anaconda3\\envs\\pytorch\\lib\\site-packages\\IPython\\core\\ultratb.py\", line 1169, in get_records\n",
      "    return _fixed_getinnerframes(etb, number_of_lines_of_context, tb_offset)\n",
      "  File \"D:\\Anaconda3\\envs\\pytorch\\lib\\site-packages\\IPython\\core\\ultratb.py\", line 316, in wrapped\n",
      "    return f(*args, **kwargs)\n",
      "  File \"D:\\Anaconda3\\envs\\pytorch\\lib\\site-packages\\IPython\\core\\ultratb.py\", line 350, in _fixed_getinnerframes\n",
      "    records = fix_frame_records_filenames(inspect.getinnerframes(etb, context))\n",
      "  File \"D:\\Anaconda3\\envs\\pytorch\\lib\\inspect.py\", line 1490, in getinnerframes\n",
      "    frameinfo = (tb.tb_frame,) + getframeinfo(tb, context)\n",
      "  File \"D:\\Anaconda3\\envs\\pytorch\\lib\\inspect.py\", line 1448, in getframeinfo\n",
      "    filename = getsourcefile(frame) or getfile(frame)\n",
      "  File \"D:\\Anaconda3\\envs\\pytorch\\lib\\inspect.py\", line 696, in getsourcefile\n",
      "    if getattr(getmodule(object, filename), '__loader__', None) is not None:\n",
      "  File \"D:\\Anaconda3\\envs\\pytorch\\lib\\inspect.py\", line 733, in getmodule\n",
      "    if ismodule(module) and hasattr(module, '__file__'):\n",
      "  File \"D:\\Anaconda3\\envs\\pytorch\\lib\\site-packages\\tensorflow\\__init__.py\", line 50, in __getattr__\n",
      "    module = self._load()\n",
      "  File \"D:\\Anaconda3\\envs\\pytorch\\lib\\site-packages\\tensorflow\\__init__.py\", line 44, in _load\n",
      "    module = _importlib.import_module(self.__name__)\n",
      "  File \"D:\\Anaconda3\\envs\\pytorch\\lib\\importlib\\__init__.py\", line 126, in import_module\n",
      "    return _bootstrap._gcd_import(name[level:], package, level)\n",
      "  File \"<frozen importlib._bootstrap>\", line 994, in _gcd_import\n",
      "  File \"<frozen importlib._bootstrap>\", line 971, in _find_and_load\n",
      "  File \"<frozen importlib._bootstrap>\", line 953, in _find_and_load_unlocked\n",
      "ModuleNotFoundError: No module named 'tensorflow_core.estimator'\n"
     ]
    }
   ],
   "source": [
    "for i in range(1000):\n",
    "    loss = train_one_step(model, xs, ys)\n",
    "    if i % 100 == 1:\n",
    "        print(f'loss is {loss:.4}')\n",
    "        \n",
    "        \n",
    "y_preds = predict(model, xs)\n",
    "std = evaluate(ys, y_preds)\n",
    "print('训练集预测值与真实值的标准差：{:.1f}'.format(std))\n",
    "\n",
    "(xs_test, ys_test), (o_x_test, o_y_test) = load_data('test.txt')\n",
    "\n",
    "y_test_preds = predict(model, xs_test)\n",
    "std = evaluate(ys_test, y_test_preds)\n",
    "print('训练集预测值与真实值的标准差：{:.1f}'.format(std))\n",
    "\n",
    "plt.plot(o_x, o_y, 'ro', markersize=3)\n",
    "plt.plot(o_x_test, y_test_preds, 'k')\n",
    "plt.xlabel('x')\n",
    "plt.ylabel('y')\n",
    "plt.title('Linear Regression')\n",
    "plt.legend(['train', 'test', 'pred'])\n",
    "plt.show()\n"
   ]
  },
  {
   "cell_type": "code",
   "execution_count": null,
   "outputs": [],
   "source": [],
   "metadata": {
    "collapsed": false
   }
  }
 ],
 "metadata": {
  "kernelspec": {
   "display_name": "Python 3",
   "language": "python",
   "name": "python3"
  },
  "language_info": {
   "codemirror_mode": {
    "name": "ipython",
    "version": 3
   },
   "file_extension": ".py",
   "mimetype": "text/x-python",
   "name": "python",
   "nbconvert_exporter": "python",
   "pygments_lexer": "ipython3",
   "version": "3.7.0"
  }
 },
 "nbformat": 4,
 "nbformat_minor": 2
}
